## 上大分

- [x] [解决 Vercel 在国内无法访问](https://adunm.top/posts/4a17b151/)

  - [x] #### 到域名商添加记录

    ```
    A记录修改为：
    76.223.126.88
    
    cname记录修改为：
    cname-china.vercel-dns.com （推荐）
    ```

## 理解

- [Promise.prototype.then() | MDN](https://developer.mozilla.org/zh-CN/docs/Web/JavaScript/Reference/Global_Objects/Promise/then)

  - `then()` 方法返回一个新的 Promise 对象。如果在同一 Promise 对象上两次调用 `then()` 方法（而不是链式调用），则该 Promise 对象将具有两对处理方法。附加到同一 Promise 对象的所有处理方法总是按照它们添加的顺序调用。此外，每次调用 `then()` 方法返回的两个 Promise 对象开始了独立的链，不会等待彼此的敲定。

- ```js
  // 下面代码输出不理解
  Promise.resolve(1).then(2).then(console.log); // 1
  Promise.reject(1).then(2, 2).then(console.log, console.log); // 1
  ```

  - 这段代码涉及到了 Promise 的行为和参数传递，让我们一步步来理解它。

    首先，让我们看一下第一行代码：

    ```javascript
    Promise.resolve(1).then(2).then(console.log); // 1
    ```

    1. `Promise.resolve(1)` 创建了一个 Promise 对象，并将其状态设置为已解决（fulfilled）并且结果为 1。
    2. `.then(2)` 调用了 Promise 对象的 `then()` 方法，但这里传递的参数 2 并不是一个函数，而是一个数字。在规范中，`.then()` 方法期望接受两个回调函数作为参数，第一个是 `onFulfilled`，第二个是 `onRejected`。因此，传递一个数字 2 并不符合规范，但 JavaScript 引擎通常会忽略不是函数的参数。
    3. `.then(console.log)` 添加了一个回调函数 `console.log`，该函数会在 Promise 解决时被调用，并接收解决值作为参数。

    因此，第一行代码等效于以下代码：

    ```javascript
    Promise.resolve(1).then(function (value) {
      return console.log(value);
    }); // 1
    ```

    这里的 `console.log` 函数会接收解决值 1 并打印出来，所以输出是 1。

    现在，让我们看一下第二行代码：

    ```javascript
    Promise.reject(1).then(2, 2).then(console.log, console.log); // 1
    ```

    1. `Promise.reject(1)` 创建了一个 Promise 对象，并将其状态设置为已拒绝（rejected）并且拒绝原因为 1。
    2. `.then(2, 2)` 调用了 Promise 对象的 `then()` 方法，但这里传递了两个参数 2，而不是回调函数。根据规范，`.then()` 方法的第一个参数是 `onFulfilled` 回调函数，第二个参数是 `onRejected` 回调函数。这里传递的参数 2 会被忽略。
    3. `.then(console.log, console.log)` 添加了两个回调函数，第一个用于处理 Promise 解决时的情况，第二个用于处理 Promise 拒绝时的情况。

    因此，第二行代码等效于以下代码：

    ```javascript
    Promise.reject(1).then(undefined, function (reason) {
      return console.log(reason);
    }).then(undefined, function (reason) {
      return console.log(reason);
    }); // 1
    ```

    这里的两个 `console.log` 函数分别接收到拒绝原因 1，并打印出来。所以输出是 1。

    总结：虽然传递数字 2 并不符合规范，但 JavaScript 引擎通常会忽略不是函数的参数，并继续执行。这会导致回调函数不会被调用，但 Promise 的状态仍然会被传递。因此，在这个示例中，Promise 的状态是拒绝，拒绝原因是 1，然后两个回调函数都接收到这个拒绝原因并打印出来。

- ```js
  // 这里定时器的执行在下面的return string;之后吗？
  
    // 2. 接收 "foobar", 放入一个异步函数中处理该字符串
    // 并将其打印到控制台中，但是不将处理后的字符串返回到下一个。
    .then((string) => {
      setTimeout(() => {
        string += "baz";
        console.log(string); // foobarbaz
      }, 1);
      return string;
    })
  ```

  - 在你提供的代码中，`setTimeout` 是一个异步操作，它会在当前 JavaScript 事件循环的下一个周期中执行，因此会在 `return string;` 之后执行。

    具体执行流程如下：

    1. 首先，Promise 链中的前一个操作（可能是一个异步操作或其他操作）会将结果传递给这个 `.then` 方法。

    2. 然后，`.then((string) => {...})` 中的回调函数会被添加到 Promise 链中，并在前一个操作完成后执行。

    3. 在回调函数内部，`setTimeout` 被调用，并且它的回调函数将在下一个事件循环周期中执行。这是因为 JavaScript 是单线程的，它需要等待当前的执行栈清空后才会执行下一个事件循环。

    4. `return string;` 会立即执行并将 `string` 的值返回到下一个 `.then`，但是在这个时候，`string` 还没有被修改，仍然是原始的值。

    5. 然后，`setTimeout` 的回调函数执行，修改了 `string` 的值，但是这个修改对当前 `.then` 方法的返回值没有影响，因为返回值已经确定并且已经传递给下一个 `.then`。

    所以，`return string;` 会在 `setTimeout` 的回调函数之前执行，但 `string` 的修改不会影响到前一个 `.then` 方法的返回值。如果你希望等待 `setTimeout` 的完成，并将修改后的值传递给下一个 `.then`，可以通过返回一个 Promise 来实现。例如：

    ```javascript
    .then((string) => {
      return new Promise((resolve) => {
        setTimeout(() => {
          string += "baz";
          console.log(string); // foobarbaz
          resolve(string);
        }, 1);
      });
    })
    ```

    这样，你可以确保在 `setTimeout` 的回调函数执行后，将修改后的  `string` 传递给下一个 `.then`。

- ```js
  // 这个可以注意一下
  
  const p2 = new Promise((resolve, reject) => {
    resolve(1);
  });
  
  p2.then((value) => {
    console.log(value); // 1
    return value + 1;
  }).then((value) => {
    console.log(value, "- A synchronous value works"); // 2 - A synchronous value works
  });
  
  p2.then((value) => {
    console.log(value); // 1
  });
  
  ```

- **如果返回值不是一个 Promise 对象，则会隐式地将其包装在 Promise 中，然后解决。**

  - 这句话指的是在 JavaScript 中，如果你在一个 `then()` 方法中返回一个非 Promise 对象的值（例如，一个普通的 JavaScript 对象、数字、字符串等），那么 JavaScript 引擎会隐式地将这个值包装在一个新的 Promise 对象中，然后将这个 Promise 对象标记为已解决（fulfilled）状态，并且解决值就是你返回的那个非 Promise 对象。

    具体来说：

    1. 当你在一个 `then()` 方法中返回一个非 Promise 对象（例如，`return "Hello"`），JavaScript 会自动将其包装成一个 Promise 对象。

    2. 这个新的 Promise 对象会被解决为已解决状态，其解决值就是你返回的非 Promise 对象的值。

    这个机制使得 Promise 链可以持续执行，即使某个步骤返回的是普通值而不是 Promise 对象。这种自动包装的行为是 Promise 的一种便利功能，它确保了链式调用的连续性。

    例如，下面的代码演示了这一点：

    ```javascript
    Promise.resolve(1)
      .then((value) => {
        // 返回一个普通值
        return value + 1; // 返回的是 2，不是 Promise 对象
      })
      .then((result) => {
        console.log(result); // 输出 2
      });
    ```

    在上面的代码中，第一个 `then` 方法返回了一个普通值 `2`，而不是 Promise 对象，但 JavaScript 会自动将其包装成 Promise 并将解决值传递给下一个 `then` 方法。这样，你可以在 Promise 链中混合使用 Promise 对象和普通值，而不需要手动创建新的 Promise 对象。

​	

## 记忆

- 你可以使用链式调用，在一个函数上实现基于 Promise 的 API，在另一个函数之上。
  ```js
  function fetchCurrentData() {
    // fetch() API 返回一个 Promise。
    // 这个函数提供了一个类似的 API，但是它对 Promise 的兑现值进行了更多处理
    return fetch("current-data.json").then((response) => {
      if (response.headers.get("content-type") !== "application/json") {
        throw new TypeError();
      }
      const j = response.json();
      // 可以对 j 进行一些处理
  
      // 兑现值将会传递给 fetchCurrentData().then() 中的处理函数
      return j;
    });
  }
  
  ```

- ## [描述](https://developer.mozilla.org/zh-CN/docs/Web/JavaScript/Reference/Global_Objects/Promise/catch#描述)

  `catch` 方法用于在 Promise 链进行错误处理，因为它总是会返回一个 [`Promise`](https://developer.mozilla.org/zh-CN/docs/Web/JavaScript/Reference/Global_Objects/Promise)，所以它可以和 [`then()`](https://developer.mozilla.org/zh-CN/docs/Web/JavaScript/Reference/Global_Objects/Promise/then) 方法一样被[链式调用](https://developer.mozilla.org/zh-CN/docs/Web/JavaScript/Guide/Using_promises#catch_的后续链式操作)。

  如果一个 promise 被拒绝并且没有可调用的拒绝处理器（处理器可以是 [`Promise.prototype.then()`](https://developer.mozilla.org/zh-CN/docs/Web/JavaScript/Reference/Global_Objects/Promise/then)、[`Promise.prototype.catch()`](https://developer.mozilla.org/zh-CN/docs/Web/JavaScript/Reference/Global_Objects/Promise/catch) 或 [`Promise.prototype.finally()`](https://developer.mozilla.org/zh-CN/docs/Web/JavaScript/Reference/Global_Objects/Promise/finally)），则拒绝事件由宿主环境来提供。在浏览器中，这将触发 [`unhandledrejection`](https://developer.mozilla.org/zh-CN/docs/Web/API/Window/unhandledrejection_event) 事件。如果将一个处理器附加到一个已被拒绝，且已导致未处理的拒绝事件的 promise，将会触发 [`rejectionhandled`](https://developer.mozilla.org/zh-CN/docs/Web/API/Window/rejectionhandled_event) 事件。

  `catch()` 方法内部会调用当前 promise 对象的 `then()` 方法，并将 `undefined` 和 `onRejected` 作为参数传递给 `then()`。该调用的返回值直接被返回。如果你对这些方法进行封装，这一点是可以观察到的。

  JSCopy to Clipboard

  ```js
  // 重写原本的 Promise.prototype.then/catch 方法，只是为了添加一些日志
  ((Promise) => {
    const originalThen = Promise.prototype.then;
    const originalCatch = Promise.prototype.catch;
  
    Promise.prototype.then = function (...args) {
      console.log("在 %o 上调用 .then 方法，参数为：%o", this, args);
      return originalThen.apply(this, args);
    };
    Promise.prototype.catch = function (...args) {
      console.error("在 %o 上调用 .catch 方法，参数为：%o", this, args);
      return originalCatch.apply(this, args);
    };
  })(Promise);
  
  // 对已经解决的 Promise 调用 catch
  Promise.resolve().catch(function XXX() {});
  
  // 输出：
  // 在 Promise{} 上调用 .catch，参数为：Arguments{1} [0: function XXX()]
  // 在 Promise{} 上调用 .then，参数为：Arguments{2} [0: undefined, 1: function XXX()]
  ```

  这意味着传入 `undefined` 仍然会导致返回的 promise 被拒绝，你必须传入一个函数来防止最终的 promise 被拒绝。

  因为 `catch()` 只是单纯的调用了 `then()`，它支持子类化。

- 在调用 `resolve` 之后抛出的错误会被忽略：
  ```js
  const p3 = new Promise((resolve, reject) => {
    resolve();
    throw new Error("Silenced Exception!");
  });
  
  p3.catch((e) => {
    console.error(e); // 这里永远不会执行
  });
  
  ```

  

## 提问

### Promise.prototype.then的onFulfilled 和 onRejected 是在两个分别的线程中还是进程中

在 JavaScript 中，`Promise.prototype.then` 方法中的 `onFulfilled` 和 `onRejected` 回调函数通常在单一线程中执行，而不是在不同的线程或进程中执行。这个单一线程通常是 JavaScript 运行时的主线程，负责执行 JavaScript 代码。

当 Promise 对象的状态从等待（pending）变为已解决（fulfilled）或已拒绝（rejected）时，相关的回调函数会被添加到一个任务队列（也称为事件队列或微任务队列）中。然后，JavaScript 主线程会从任务队列中取出任务并执行它们。这确保了 `onFulfilled` 和 `onRejected` 回调函数是按顺序执行的，而不会并发运行在不同的线程或进程中。

这种单线程的执行模型使得 JavaScript 具有简单且可预测的行为，因为它避免了多线程并发问题。但需要注意的是，如果 `onFulfilled` 或 `onRejected` 回调函数中包含了耗时的操作，可能会阻塞主线程，导致页面或应用程序响应性降低。为了避免这种情况，可以考虑使用 `async/await` 或将耗时操作委托给 Web Workers 等多线程机制，以在后台执行这些操作，从而不会阻塞主线程。

​	

### 那这句话怎么理解：此外，每次调用 then() 方法返回的两个 Promise 对象开始了独立的链，不会等待彼此的敲定。

这句话的意思是，每次你调用 `then()` 方法并添加回调函数时，它会返回一个全新的 Promise 对象，而这个新的 Promise 对象和之前的 Promise 对象是独立的，它们不会相互等待彼此的完成或敲定状态。

让我们分解一下这句话：

1. "每次调用 `then()` 方法"：这意味着你可以多次调用 `then()` 方法，每次都可以添加一个回调函数到 Promise 链中。

2. "返回的两个 Promise 对象"：每次调用 `then()` 方法都会返回一个新的 Promise 对象。这个新的 Promise 对象代表了当前回调函数的结果。

3. "开始了独立的链"：新的 Promise 对象和之前的 Promise 对象之间没有直接的关联，它们是独立的。这意味着它们的状态和结果不会相互影响，它们各自都有自己的状态迁移和回调函数队列。

4. "不会等待彼此的敲定"：这表示新的 Promise 对象不会等待之前的 Promise 对象完成，它们之间没有依赖关系。如果你在多个 `then()` 中添加回调函数，它们可以同时执行，而不会阻塞或等待彼此。

这种独立的 Promise 链可以用于构建复杂的异步操作序列，其中每个 `then()` 方法都表示一个独立的步骤，它们可以并行执行，提高了并发性。但同时，也需要小心处理这些独立链之间的错误处理和结果传递，以确保整个操作流程按照预期执行。

​	

### 如果一个promise在链式调用中执行catch，那么catch后面链式调用的第一个then是执行onfulfilled还是onRejected 函数吗？

在一个 Promise 链式调用中，如果在链中的某个位置调用了 `catch` 方法，那么接下来的链式调用中的第一个 `then` 方法将执行 `onFulfilled` 函数，而不是 `onRejected` 函数。

这是因为 `catch` 方法是用来捕获前面任何一个 Promise 链中的错误（即前面任何一个 Promise 被拒绝的情况），并返回一个新的 Promise，这个新的 Promise 的状态是已解决（resolved）。因此，如果在 `catch` 后面继续链式调用，下一个 `then` 将被认为是在前一个 Promise 被解决时执行。

例如：

```javascript
promise
  .then(onFulfilled1)
  .catch(onRejected)
  .then(onFulfilled2);
```

在上面的代码中，如果 `promise` 被拒绝，那么 `onRejected` 会被调用，但接下来的 `then` (`onFulfilled2`) 会被执行，因为 `catch` 返回的 Promise 是已解决状态。如果 `promise` 被解决，那么 `onFulfilled1` 会被执行，然后接下来的 `then` (`onFulfilled2`) 也会被执行。这是 Promise 链式调用中的一种常见用法，用于处理错误和继续执行。

​	

### try...catch 和 then catch 有什么区别

`try...catch` 和 `then` 中的 `catch` 用于处理错误，但它们之间有很大的区别，主要在于它们的工作方式和用途：

1. `try...catch`：
   - `try...catch` 是 JavaScript 中的异常处理机制，用于捕获同步代码块中的异常（错误）。
   - 它只能捕获同步代码中的异常，不能捕获异步操作的错误，比如 Promise 中的错误或者定时器中的错误。
   - 当代码块中发生异常时，程序会立即跳转到 `catch` 块，执行 `catch` 块中的代码，然后继续执行后续代码。
   - 适用于处理同步代码中的错误，通常用于处理一些可预见的异常情况。

```javascript
try {
  // 同步代码块，可能会抛出异常
  throw new Error('Something went wrong');
} catch (error) {
  // 异常被捕获，进行错误处理
  console.error(error);
}
```

2. `then` 和 `catch`（Promise 链）：
   - `then` 和 `catch` 用于处理异步操作的结果和错误，主要用于处理 Promise 对象。
   - 它们是用来注册回调函数的方法，允许你指定在 Promise 完成时（解决或拒绝）要执行的操作。
   - `then` 用于处理成功时的情况（Promise 被解决），而 `catch` 用于处理失败时的情况（Promise 被拒绝）。
   - 可以链式调用多个 `then` 来处理多个异步操作的结果，以及一个 `catch` 来捕获链中的任何错误。

```javascript
promise
  .then(result => {
    // 处理成功情况
  })
  .catch(error => {
    // 处理失败情况
  });
```

总之，`try...catch` 主要用于同步代码块中的异常处理，而 `then` 和 `catch` 主要用于异步操作的结果和错误处理，特别是在 Promise 链中使用，以便更好地处理异步流程中的错误和成功情况。

​	

### new promise的时候只接收一个参数吗，不是接收两个参数吗

`Promise` 构造函数**接受一个参数，这个参数是一个函数，该函数有两个参数**，分别是 `resolve` 和 `reject`，用于控制 Promise 的状态。这个函数在创建 Promise 时立即执行。这个函数通常被称为执行器（executor）。

所以，你的观察是正确的，`Promise` 构造函数实际上接受两个参数，但这两个参数都被封装到一个函数中，而不是分开的两个参数。这是 `Promise` 的基本用法示例：

```javascript
// 创建一个 Promise，其中的执行器函数接受 resolve 和 reject 参数
const promise = new Promise((resolve, reject) => {
  // 模拟一个异步操作，比如从服务器获取数据
  setTimeout(() => {
    const randomNumber = Math.random(); // 模拟操作的结果

    // 如果操作成功，解决 Promise 并传递结果
    if (randomNumber > 0.5) {
      resolve(`操作成功，随机数为 ${randomNumber}`);
    } else {
      // 如果操作失败，拒绝 Promise 并传递错误信息
      reject(new Error(`操作失败，随机数为 ${randomNumber}`));
    }
  }, 1000); // 模拟1秒钟的异步操作
});

// 处理 Promise 的结果或错误
promise
  .then(result => {
    console.log(`Promise 已解决：${result}`);
  })
  .catch(error => {
    console.error(`Promise 已拒绝：${error.message}`);
  });

```

在这个示例中，我们创建了一个 Promise，在执行器函数内模拟了一个异步操作（使用 `setTimeout` 模拟延迟），然后根据随机生成的数字来解决或拒绝 Promise。接着，我们使用 `.then` 方法来处理成功情况，并使用 `.catch` 方法来处理失败情况。

请注意，执行器函数内部的异步操作是模拟的，实际应用中可以是任何异步操作，例如从服务器获取数据、读取文件等。当异步操作完成时，根据操作结果使用 `resolve` 或 `reject` 来决定 Promise 的最终状态。